/home/zhli/Current-Work/Pcam_Experiment/dataset/DATA/pcamv1/camelyonpatch_level_2_split_train
/home/zhli/Current-Work/Pcam_Experiment/dataset/DATA/pcamv1/camelyonpatch_level_2_split_train
/home/zhli/Current-Work/Pcam_Experiment/dataset/DATA/pcamv1/camelyonpatch_level_2_split_test
/home/zhli/Current-Work/Pcam_Experiment/dataset/DATA/pcamv1/camelyonpatch_level_2_split_test
/home/zhli/Current-Work/Pcam_Experiment/dataset/DATA/pcamv1/camelyonpatch_level_2_split_valid
/home/zhli/Current-Work/Pcam_Experiment/dataset/DATA/pcamv1/camelyonpatch_level_2_split_valid
  0%|                                            | 0/2048 [00:01<?, ?it/s]
Traceback (most recent call last):
  File "train_rn18_base.py", line 123, in <module>
    train(train_dataset, test_dataset, model_backbone, max_epoch)
  File "train_rn18_base.py", line 62, in train
    y_pred = model.forward(images)
  File "/opt/anaconda/envs/dassl/lib/python3.8/site-packages/torch/nn/parallel/data_parallel.py", line 168, in forward
    outputs = self.parallel_apply(replicas, inputs, kwargs)
  File "/opt/anaconda/envs/dassl/lib/python3.8/site-packages/torch/nn/parallel/data_parallel.py", line 178, in parallel_apply
    return parallel_apply(replicas, inputs, kwargs, self.device_ids[:len(replicas)])
  File "/opt/anaconda/envs/dassl/lib/python3.8/site-packages/torch/nn/parallel/parallel_apply.py", line 86, in parallel_apply
    output.reraise()
  File "/opt/anaconda/envs/dassl/lib/python3.8/site-packages/torch/_utils.py", line 461, in reraise
    raise exception
RuntimeError: Caught RuntimeError in replica 0 on device 0.
Original Traceback (most recent call last):
  File "/opt/anaconda/envs/dassl/lib/python3.8/site-packages/torch/nn/parallel/parallel_apply.py", line 61, in _worker
    output = module(*input, **kwargs)
  File "/opt/anaconda/envs/dassl/lib/python3.8/site-packages/torch/nn/modules/module.py", line 1130, in _call_impl
    return forward_call(*input, **kwargs)
  File "/opt/anaconda/envs/dassl/lib/python3.8/site-packages/torchvision/models/resnet.py", line 285, in forward
    return self._forward_impl(x)
  File "/opt/anaconda/envs/dassl/lib/python3.8/site-packages/torchvision/models/resnet.py", line 268, in _forward_impl
    x = self.conv1(x)
  File "/opt/anaconda/envs/dassl/lib/python3.8/site-packages/torch/nn/modules/module.py", line 1130, in _call_impl
    return forward_call(*input, **kwargs)
  File "/opt/anaconda/envs/dassl/lib/python3.8/site-packages/torch/nn/modules/conv.py", line 457, in forward
    return self._conv_forward(input, self.weight, self.bias)
  File "/opt/anaconda/envs/dassl/lib/python3.8/site-packages/torch/nn/modules/conv.py", line 453, in _conv_forward
    return F.conv2d(input, weight, bias, self.stride,
RuntimeError: Given groups=1, weight of size [64, 3, 7, 7], expected input[64, 1, 96, 96] to have 3 channels, but got 1 channels instead